[2025-03-13T18:23:47.670+0000] {local_task_job_runner.py:123} INFO - ::group::Pre task execution logs
[2025-03-13T18:23:47.679+0000] {taskinstance.py:2614} INFO - Dependencies all met for dep_context=non-requeueable deps ti=<TaskInstance: parse_FT.get_daily_listing_task manual__2025-03-13T18:23:44.029581+00:00 [queued]>
[2025-03-13T18:23:47.683+0000] {taskinstance.py:2614} INFO - Dependencies all met for dep_context=requeueable deps ti=<TaskInstance: parse_FT.get_daily_listing_task manual__2025-03-13T18:23:44.029581+00:00 [queued]>
[2025-03-13T18:23:47.684+0000] {taskinstance.py:2867} INFO - Starting attempt 1 of 2
[2025-03-13T18:23:47.691+0000] {taskinstance.py:2890} INFO - Executing <Task(PythonOperator): get_daily_listing_task> on 2025-03-13 18:23:44.029581+00:00
[2025-03-13T18:23:47.695+0000] {warnings.py:112} WARNING - /home/***/.local/lib/python3.12/site-packages/***/task/task_runner/standard_task_runner.py:70: DeprecationWarning: This process (pid=1737) is multi-threaded, use of fork() may lead to deadlocks in the child.
  pid = os.fork()

[2025-03-13T18:23:47.696+0000] {standard_task_runner.py:72} INFO - Started process 1739 to run task
[2025-03-13T18:23:47.696+0000] {standard_task_runner.py:104} INFO - Running: ['***', 'tasks', 'run', 'parse_FT', 'get_daily_listing_task', 'manual__2025-03-13T18:23:44.029581+00:00', '--job-id', '14', '--raw', '--subdir', 'DAGS_FOLDER/scraping.py', '--cfg-path', '/tmp/tmprjvuwrb4']
[2025-03-13T18:23:47.696+0000] {standard_task_runner.py:105} INFO - Job 14: Subtask get_daily_listing_task
[2025-03-13T18:23:47.720+0000] {task_command.py:467} INFO - Running <TaskInstance: parse_FT.get_daily_listing_task manual__2025-03-13T18:23:44.029581+00:00 [running]> on host 5ab3e0664f49
[2025-03-13T18:23:47.766+0000] {taskinstance.py:3134} INFO - Exporting env vars: AIRFLOW_CTX_DAG_OWNER='joel' AIRFLOW_CTX_DAG_ID='parse_FT' AIRFLOW_CTX_TASK_ID='get_daily_listing_task' AIRFLOW_CTX_EXECUTION_DATE='2025-03-13T18:23:44.029581+00:00' AIRFLOW_CTX_TRY_NUMBER='1' AIRFLOW_CTX_DAG_RUN_ID='manual__2025-03-13T18:23:44.029581+00:00'
[2025-03-13T18:23:47.767+0000] {logging_mixin.py:190} INFO - Task instance is in running state
[2025-03-13T18:23:47.767+0000] {logging_mixin.py:190} INFO -  Previous state of the Task instance: queued
[2025-03-13T18:23:47.768+0000] {logging_mixin.py:190} INFO - Current task name:get_daily_listing_task state:running start_date:2025-03-13 18:23:47.679827+00:00
[2025-03-13T18:23:47.768+0000] {logging_mixin.py:190} INFO - Dag name:parse_FT and current dag run status:running
[2025-03-13T18:23:47.768+0000] {taskinstance.py:732} INFO - ::endgroup::
[2025-03-13T18:23:47.769+0000] {taskinstance.py:3313} ERROR - Task failed with exception
Traceback (most recent call last):
  File "/home/airflow/.local/lib/python3.12/site-packages/airflow/models/taskinstance.py", line 768, in _execute_task
    result = _execute_callable(context=context, **execute_callable_kwargs)
             ^^^^^^^^^^^^^^^^^^^^^^^^^^^^^^^^^^^^^^^^^^^^^^^^^^^^^^^^^^^^^
  File "/home/airflow/.local/lib/python3.12/site-packages/airflow/models/taskinstance.py", line 734, in _execute_callable
    return ExecutionCallableRunner(
           ^^^^^^^^^^^^^^^^^^^^^^^^
  File "/home/airflow/.local/lib/python3.12/site-packages/airflow/utils/operator_helpers.py", line 252, in run
    return self.func(*args, **kwargs)
           ^^^^^^^^^^^^^^^^^^^^^^^^^^
  File "/home/airflow/.local/lib/python3.12/site-packages/airflow/models/baseoperator.py", line 424, in wrapper
    return func(self, *args, **kwargs)
           ^^^^^^^^^^^^^^^^^^^^^^^^^^^
  File "/home/airflow/.local/lib/python3.12/site-packages/airflow/operators/python.py", line 238, in execute
    return_value = self.execute_callable()
                   ^^^^^^^^^^^^^^^^^^^^^^^
  File "/home/airflow/.local/lib/python3.12/site-packages/airflow/operators/python.py", line 256, in execute_callable
    return runner.run(*self.op_args, **self.op_kwargs)
           ^^^^^^^^^^^^^^^^^^^^^^^^^^^^^^^^^^^^^^^^^^^
  File "/home/airflow/.local/lib/python3.12/site-packages/airflow/utils/operator_helpers.py", line 252, in run
    return self.func(*args, **kwargs)
           ^^^^^^^^^^^^^^^^^^^^^^^^^^
  File "/opt/airflow/dags/scraping.py", line 173, in get_daily_listing
    with open("/data/urls.txt", "w") as f:
         ^^^^^^^^^^^^^^^^^^^^^^^^^^^
FileNotFoundError: [Errno 2] No such file or directory: '/data/urls.txt'
[2025-03-13T18:23:47.778+0000] {logging_mixin.py:190} INFO - Task instance in failure state
[2025-03-13T18:23:47.778+0000] {logging_mixin.py:190} INFO - Task start:2025-03-13 18:23:47.679827+00:00 end:2025-03-13 18:23:47.778072+00:00 duration:0.098245
[2025-03-13T18:23:47.778+0000] {logging_mixin.py:190} INFO - Task:<Task(PythonOperator): get_daily_listing_task> dag:<DAG: parse_FT> dagrun:<DagRun parse_FT @ 2025-03-13 18:23:44.029581+00:00: manual__2025-03-13T18:23:44.029581+00:00, state:running, queued_at: 2025-03-13 18:23:44.042466+00:00. externally triggered: True>
[2025-03-13T18:23:47.779+0000] {logging_mixin.py:190} INFO - Failure caused by [Errno 2] No such file or directory: '/data/urls.txt'
[2025-03-13T18:23:47.779+0000] {taskinstance.py:1226} INFO - Marking task as UP_FOR_RETRY. dag_id=parse_FT, task_id=get_daily_listing_task, run_id=manual__2025-03-13T18:23:44.029581+00:00, execution_date=20250313T182344, start_date=20250313T182347, end_date=20250313T182347
[2025-03-13T18:23:47.794+0000] {taskinstance.py:341} INFO - ::group::Post task execution logs
[2025-03-13T18:23:47.794+0000] {standard_task_runner.py:124} ERROR - Failed to execute job 14 for task get_daily_listing_task ([Errno 2] No such file or directory: '/data/urls.txt'; 1739)
Traceback (most recent call last):
  File "/home/airflow/.local/lib/python3.12/site-packages/airflow/task/task_runner/standard_task_runner.py", line 117, in _start_by_fork
    ret = args.func(args, dag=self.dag)
          ^^^^^^^^^^^^^^^^^^^^^^^^^^^^^
  File "/home/airflow/.local/lib/python3.12/site-packages/airflow/cli/cli_config.py", line 49, in command
    return func(*args, **kwargs)
           ^^^^^^^^^^^^^^^^^^^^^
  File "/home/airflow/.local/lib/python3.12/site-packages/airflow/utils/cli.py", line 116, in wrapper
    return f(*args, **kwargs)
           ^^^^^^^^^^^^^^^^^^
  File "/home/airflow/.local/lib/python3.12/site-packages/airflow/cli/commands/task_command.py", line 483, in task_run
    task_return_code = _run_task_by_selected_method(args, _dag, ti)
                       ^^^^^^^^^^^^^^^^^^^^^^^^^^^^^^^^^^^^^^^^^^^^
  File "/home/airflow/.local/lib/python3.12/site-packages/airflow/cli/commands/task_command.py", line 256, in _run_task_by_selected_method
    return _run_raw_task(args, ti)
           ^^^^^^^^^^^^^^^^^^^^^^^
  File "/home/airflow/.local/lib/python3.12/site-packages/airflow/cli/commands/task_command.py", line 341, in _run_raw_task
    return ti._run_raw_task(
           ^^^^^^^^^^^^^^^^^
  File "/home/airflow/.local/lib/python3.12/site-packages/airflow/utils/session.py", line 97, in wrapper
    return func(*args, session=session, **kwargs)
           ^^^^^^^^^^^^^^^^^^^^^^^^^^^^^^^^^^^^^^
  File "/home/airflow/.local/lib/python3.12/site-packages/airflow/models/taskinstance.py", line 3006, in _run_raw_task
    return _run_raw_task(
           ^^^^^^^^^^^^^^
  File "/home/airflow/.local/lib/python3.12/site-packages/airflow/models/taskinstance.py", line 274, in _run_raw_task
    TaskInstance._execute_task_with_callbacks(
  File "/home/airflow/.local/lib/python3.12/site-packages/airflow/models/taskinstance.py", line 3161, in _execute_task_with_callbacks
    result = self._execute_task(context, task_orig)
             ^^^^^^^^^^^^^^^^^^^^^^^^^^^^^^^^^^^^^^
  File "/home/airflow/.local/lib/python3.12/site-packages/airflow/models/taskinstance.py", line 3185, in _execute_task
    return _execute_task(self, context, task_orig)
           ^^^^^^^^^^^^^^^^^^^^^^^^^^^^^^^^^^^^^^^
  File "/home/airflow/.local/lib/python3.12/site-packages/airflow/models/taskinstance.py", line 768, in _execute_task
    result = _execute_callable(context=context, **execute_callable_kwargs)
             ^^^^^^^^^^^^^^^^^^^^^^^^^^^^^^^^^^^^^^^^^^^^^^^^^^^^^^^^^^^^^
  File "/home/airflow/.local/lib/python3.12/site-packages/airflow/models/taskinstance.py", line 734, in _execute_callable
    return ExecutionCallableRunner(
           ^^^^^^^^^^^^^^^^^^^^^^^^
  File "/home/airflow/.local/lib/python3.12/site-packages/airflow/utils/operator_helpers.py", line 252, in run
    return self.func(*args, **kwargs)
           ^^^^^^^^^^^^^^^^^^^^^^^^^^
  File "/home/airflow/.local/lib/python3.12/site-packages/airflow/models/baseoperator.py", line 424, in wrapper
    return func(self, *args, **kwargs)
           ^^^^^^^^^^^^^^^^^^^^^^^^^^^
  File "/home/airflow/.local/lib/python3.12/site-packages/airflow/operators/python.py", line 238, in execute
    return_value = self.execute_callable()
                   ^^^^^^^^^^^^^^^^^^^^^^^
  File "/home/airflow/.local/lib/python3.12/site-packages/airflow/operators/python.py", line 256, in execute_callable
    return runner.run(*self.op_args, **self.op_kwargs)
           ^^^^^^^^^^^^^^^^^^^^^^^^^^^^^^^^^^^^^^^^^^^
  File "/home/airflow/.local/lib/python3.12/site-packages/airflow/utils/operator_helpers.py", line 252, in run
    return self.func(*args, **kwargs)
           ^^^^^^^^^^^^^^^^^^^^^^^^^^
  File "/opt/airflow/dags/scraping.py", line 173, in get_daily_listing
    with open("/data/urls.txt", "w") as f:
         ^^^^^^^^^^^^^^^^^^^^^^^^^^^
FileNotFoundError: [Errno 2] No such file or directory: '/data/urls.txt'
[2025-03-13T18:23:47.829+0000] {local_task_job_runner.py:266} INFO - Task exited with return code 1
[2025-03-13T18:23:47.843+0000] {taskinstance.py:3901} INFO - 0 downstream tasks scheduled from follow-on schedule check
[2025-03-13T18:23:47.844+0000] {local_task_job_runner.py:245} INFO - ::endgroup::
